Workbook

Sheet Overview
B2: OVERVIEW
B3: Sistem Rekomendasi Menu Diet Berbasis Genetic Algorithm untuk Penderita Penyakit Kronis dan Tidak Menular
B5: 1 — TENTANG SISTEM
B6: Deskripsi | C6: Sistem ini adalah aplikasi berbasis website yang membantu pengguna merencanakan menu diet harian yang dipersonalisasi. Sistem ini dibuat dengan menggunakan Genetic Algorithm (GA) dan Greedy Algorithm. Sistem ini secara otomatis akan mencari kombinasi menu terbaik yang memenuhi kebutuhan nutrisi unik setiap pengguna berdasarkan profil fisik dan kondisi kesehatannya. Terdapat 5 penyakit yang tersedia di sistem dan pengguna bisa memilih 1 hingga 3 kondisi penyakit sesuai kondisi kesehatan. Penyakit tersebut meliputi 1. Diabetes Melitus Tipe 2 2. Hipertensi 3. Kardiovaskular 4. Hiperkolesterolemia 5. Penyakit Ginjal Stadium 1
B7: Status Sistem | C7: Sistem yang dibuat merupakan Sistem Pendukung Keputusan (Decision Support System), bukan pengganti konsultasi medis. Seluruh rekomendasi yang dihasilkan bersifat panduan awal dan tetap harus dikonsultasikan kepada dokter atau tenaga gizi profesional sebelum diterapkan.
B8: Dataset | C8: Dataset berasal dari United States Department of Agriculture (USDA) National Nutrient Database, dimana dataset tersebut telah melalui proses pembersihan data (preprocessing) dilakukan dengan menghapus produk tidak layak konsumsi, produk yang tidak sesuai syariat (haram), serta data dengan nilai nutrisi tidak valid. Total data yang digunakan saat ini yakni ±2.800 item makanan dan minuman. Catatan: Dataset USDA tidak mencakup semua makanan di dunia nyata, khususnya makanan lokal Indonesia. Hal ini merupakan salah satu keterbatasan yang terbuka untuk dikritisi.
B9: Target Pengguna | C9: Masyarakat umum (internasional), sistem berbasis website dalam Bahasa Inggris, dapat diakses oleh siapa saja tanpa batasan profesi. Pengguna dengan kondisi penyakit kronis sangat disarankan untuk tetap berkonsultasi dengan tenaga medis.
B11: 2 — OUTPUT SISTEM
B12: Struktur Output (per hari) | C12: Sistem menghasilkan 1 rencana menu lengkap untuk 1 hari dengan struktur berikut: • Breakfast : Main Course, Side Dish, Drink • Lunch : Main Course, Side Dish, Drink • Dinner : Main Course, Side Dish, Drink • Snack Sistem web menghasilkan tiga pilihan menu pada setiap waktu makan. Pengguna memilih satu dari tiga alternatif tersebut sehingga terbentuk menu harian yang terdiri atas 10 item makanan/minuman. Pada lembar evaluasi ini, hanya ditampilkan menu yang dipilih pengguna sebagai representasi hasil akhir rekomendasi sistem.
B13: Distribusi Kalori per Waktu Makan | C13: Breakfast (Sarapan): 23,75% | Lunch (Makan Siang): 33,75% Dinner (Makan Malam): 28,75% | Snack: 13,75% Nilai ini merupakan konstanta yang di-hardcode dalam sistem dan menjadi salah satu aspek yang divalidasi pada Kriteria I di setiap form case.
B15: 3 — KONDISI PENYAKIT YANG DIANALISIS (13 Skenario)
B16: No | Kondisi Penyakit | C16: Nutrisi yang Dibatasi / Diprioritaskan
B17: 01 — Normal | C17: Lihat pada guideline
B18: 02 — Diabetes Melitus Tipe 2 | C18: Lihat pada guideline
B19: 03 — Hipertensi | C19: Lihat pada guideline
B20: 04 — Cardiovascular Disease (CVD) | C20: Lihat pada guideline
B21: 05 — Hiperkolesterolemia | C21: Lihat pada guideline
B22: 06 — Chronic Kidney Disease (CKD) Stadium 1 | C22: Lihat pada guideline
B23: 07 — Diabetes + Hipertensi | C23: Lihat pada guideline
B24: 08 — Diabetes + Hiperkolesterolemia | C24: Lihat pada guideline
B25: 09 — Hipertensi + CVD | C25: Lihat pada guideline
B26: 10 — CKD + Hipertensi | C26: Lihat pada guideline
B27: 11 — Diabetes + Hipertensi + Hiperkolesterolemia | C27: Lihat pada guideline
... B29: 13 — Hipertensi + Hiperkolesterolemia + CVD | C29: Lihat pada guideline
B31: 4 — PERAN AHLI GIZI DALAM VALIDASI INI
B32: Tujuan Validasi | C32: Validasi oleh ahli gizi merupakan bagian inti dari penelitian ini. Penilaian ahli gizi akan digunakan untuk mengukur sejauh mana sistem mampu menghasilkan rekomendasi yang tidak hanya valid secara komputasional, tetapi juga relevan secara klinis dan dapat diterima dalam praktik gizi nyata.
B33: Yang Dinilai (Kriteria A–I) | C33: A. Kesesuaian menu dengan kondisi penyakit B. Kesesuaian total energi harian C. Kesesuaian distribusi makronutrien (karbohidrat, protein, lemak) D. Ketepatan pembatasan nutrisi khusus per penyakit E. Realisme kombinasi menu untuk konsumsi sehari-hari F. Variasi dan keberterimaan menu G. Penilaian keseluruhan kelayakan menu H. Kesesuaian porsi dan ukuran sajian I. Ketepatan distribusi kalori per waktu makan
B34: Yang Diharapkan dari Ahli Gizi | C34: Selain skor numerik (1–5), masukan kualitatif sangat diharapkan, terutama mengenai: • Jenis makanan yang sebaiknya ditambahkan atau dikeluarkan dari database • Batasan nutrisi yang dinilai terlalu ketat atau terlalu longgar • Potensi dan hambatan implementasi sistem di fasilitas kesehatan
B36: Terima kasih atas waktu dan kontribusi Ibu Ahli Gizi. Setiap masukan sangat berharga untuk pengembangan sistem yang lebih baik

Sheet Petunjuk
B2: FORM VALIDASI AHLI GIZI
B3: Instrumen Penilaian Kualitas Sistem Rekomendasi Menu Diet Berbasis Genetic Algorithm
B4: Tugas Akhir · Sistem Pendukung Keputusan
B6: BAGIAN 1 — TUJUAN PENELITIAN
B7: Judul Penelitian | C7: Implementasi Genetic Algorithm untuk Penentuan Menu Diet Sehat Bagi Penderita Penyakit Kronis dan Tidak Menular
B8: Tujuan Utama | C8: Merancang sistem rekomendasi menu diet harian yang dipersonalisasi berdasarkan profil pengguna (usia, berat badan, tinggi badan, jenis kelamin, aktivitas, kondisi penyakit) menggunakan Genetic Algorithm (GA) dan Greedy Algorithm dengan dataset nutrisi USDA.
B9: Tujuan Validasi | C9: Mendapatkan penilaian ahli gizi klinis terhadap kualitas output menu yang dihasilkan sistem, meliputi kesesuaian nutrisi, realisme menu, ketepatan pembatasan penyakit, dan kelayakan klinis secara umum.
B11: BAGIAN 3 — PETUNJUK PENGISIAN FORM
B12: Langkah 1 | C12: Buka sheet Case 1 s.d. Case 13 secara berurutan.
B13: Langkah 2 | C13: Baca Bagian 1 (Profil User) dan Bagian 3 (Menu Rekomendasi) untuk memahami kondisi pasien.
B14: Langkah 3 | C14: Cek Bagian 2 (Kebutuhan Nutrisi), Bagian 5 (Hard Constraint), dan Bagian 6 (Soft Constraint).
B15: Langkah 4 | C15: Pada Bagian 7 (Form Penilaian), klik sel kolom SKOR lalu pilih nilai 1–5 dari dropdown. Jangan ketik manual agar Rekap terhitung otomatis.
B16: Langkah 5 | C16: Isi Bagian 8 (Komentar & Saran) dengan tiga aspek: Catatan Klinis Menu, Kesesuaian Panduan Gizi, dan Kelayakan Implementasi Klinis.
B17: Langkah 6 | C17: Ulangi Langkah 1–5 untuk semua 13 case.
B19: BAGIAN 4 — SKALA PENILAIAN (1–5)
B20: 1 — Sangat Tidak Sesuai | C20: Menu sama sekali tidak memenuhi kriteria. Terdapat kesalahan fundamental yang berpotensi membahayakan kondisi pasien.
B21: 2 — Tidak Sesuai | C21: Ada upaya pemenuhan kriteria namun masih jauh dari standar klinis. Perlu perbaikan signifikan sebelum dapat digunakan.
B22: 3 — Cukup Sesuai | C22: Memenuhi sebagian besar kriteria namun terdapat kekurangan yang perlu diperbaiki. Masih dapat diterima dengan catatan.
B23: 4 — Sesuai | C23: Memenuhi standar gizi klinis dengan baik. Kekurangan yang ada bersifat minor dan tidak signifikan secara klinis.
B24: 5 — Sangat Sesuai | C24: Memenuhi semua kriteria secara optimal sesuai pedoman gizi klinis. Layak direkomendasikan tanpa catatan perbaikan berarti.
B26: BAGIAN 5 — TAUTAN REFERENSI
B27: Website Sistem | C27: https://chronobite.vercel.app/
B28: Link Dataset USDA (yang sudah dibersihkan) | C28: Dataset Cleaned.xlsx
B29: Sumber Dataset | C29: USDA FoodData Central
B30: Link DRI (Dietary Reference Intake) | C30: Dietary Reference Intake.xlsx
B31: Sumber DRI | C31: Nutrient Recommendations and Databases
B32: Rekap Guideline Nutrisi per Penyakit | C32: Guideline.xlsx
B33: Sumber Guideline | C33: 01. Guideline

Sheet Rekap Penilaian
B2: REKAP PENILAIAN AHLI GIZI — SEMUA CASE (GENETIC ALGORITHM) | P2: REKAP PENILAIAN AHLI GIZI — SEMUA CASE (GREEDY ALGORITHM)
B3: Skor diambil otomatis dari masing-masing sheet Case. Isi data pada sheet Case 1–13 terlebih dahulu. | P3: Skor diambil otomatis dari masing-masing sheet Case. Isi data pada sheet Case 1–13 terlebih dahulu.
B5: No | C5: Kondisi Penyakit | D5: A | E5: B | F5: C | G5: D | H5: E | I5: F | J5: G | K5: H | L5: I | M5: Rata-rata | N5: Komentar | P5: No | Q5: Kondisi Penyakit | R5: A | S5: B | T5: C | U5: D | V5: E | W5: F | X5: G | Y5: H | Z5: I | AA5: Rata-rata | AB5: Komentar
D6: Kondisi Penyakit | E6: Energi | F6: Makronutrien | G6: Nutrisi Khusus | H6: Realisme | I6: Variasi | J6: Overall | K6: Porsi | L6: Distribusi Waktu | M6: Rata-rata | R6: Kondisi Penyakit | S6: Energi | T6: Makronutrien | U6: Nutrisi Khusus | V6: Realisme | W6: Variasi | X6: Overall | Y6: Porsi | Z6: Distribusi Waktu | AA6: Rata-rata
B7: 1 | C7: NORMAL | D7: ='Case 1'!E81 -> 4 | E7: ='Case 1'!E82 -> 3 | F7: ='Case 1'!E83 -> 3 | G7: ='Case 1'!E84 -> 4 | H7: ='Case 1'!E85 -> 3 | I7: ='Case 1'!E86 -> 3 | J7: ='Case 1'!E87 -> 3 | K7: ='Case 1'!E88 -> 3 | L7: ='Case 1'!E89 -> 4 | M7: =IFERROR(AVERAGE(D7,E7,F7,G7,H7,I7,J7,K7,L7),"—") -> 3.3333333 | P7: 1 | Q7: NORMAL | R7: ='Case 1'!L81 -> 4 | S7: ='Case 1'!L82 -> 3 | T7: ='Case 1'!L83 -> 3 | U7: ='Case 1'!L84 -> 4 | V7: ='Case 1'!L85 -> 3 | W7: ='Case 1'!L86 -> 3 | X7: ='Case 1'!L87 -> 3 | Y7: ='Case 1'!L88 -> 4 | Z7: ='Case 1'!L89 -> 4 | AA7: =IFERROR(AVERAGE(R7,S7,T7,U7,V7,W7,X7,Y7,Z7),"—") -> 3.4444444
B8: 2 | C8: DIABETES MELITUS TYPE 2 | D8: ='Case 2'!E81 -> 3 | E8: ='Case 2'!E82 -> 3 | F8: ='Case 2'!E83 -> 4 | G8: ='Case 2'!E84 -> 4 | H8: ='Case 2'!E85 -> 3 | I8: ='Case 2'!E86 -> 3 | J8: ='Case 2'!E87 -> 3 | K8: ='Case 2'!E88 -> 3 | L8: ='Case 2'!E89 -> 4 | M8: =IFERROR(AVERAGE(D8,E8,F8,G8,H8,I8,J8,K8,L8),"—") -> 3.3333333 | P8: 2 | Q8: DIABETES MELITUS TYPE 2 | R8: ='Case 2'!L81 -> 3 | S8: ='Case 2'!L82 -> 3 | T8: ='Case 2'!L83 -> 3 | U8: ='Case 2'!L84 -> 4 | V8: ='Case 2'!L85 -> 3 | W8: ='Case 2'!L86 -> 3 | X8: ='Case 2'!L87 -> 3 | Y8: ='Case 2'!L88 -> 4 | Z8: ='Case 2'!L89 -> 4 | AA8: =IFERROR(AVERAGE(R8,S8,T8,U8,V8,W8,X8,Y8,Z8),"—") -> 3.3333333
B9: 3 | C9: HYPERTENSION | D9: ='Case 3'!E81 -> 3 | E9: ='Case 3'!E82 -> 4 | F9: ='Case 3'!E83 -> 4 | G9: ='Case 3'!E84 -> 4 | H9: ='Case 3'!E85 -> 3 | I9: ='Case 3'!E86 -> 3 | J9: ='Case 3'!E87 -> 3 | K9: ='Case 3'!E88 -> 3 | L9: ='Case 3'!E89 -> 4 | M9: =IFERROR(AVERAGE(D9,E9,F9,G9,H9,I9,J9,K9,L9),"—") -> 3.4444444 | P9: 3 | Q9: HYPERTENSION | R9: ='Case 3'!L81 -> 3 | S9: ='Case 3'!L82 -> 4 | T9: ='Case 3'!L83 -> 4 | U9: ='Case 3'!L84 -> 2 | V9: ='Case 3'!L85 -> 3 | W9: ='Case 3'!L86 -> 3 | X9: ='Case 3'!L87 -> 3 | Y9: ='Case 3'!L88 -> 4 | Z9: ='Case 3'!L89 -> 4 | AA9: =IFERROR(AVERAGE(R9,S9,T9,U9,V9,W9,X9,Y9,Z9),"—") -> 3.3333333
B10: 4 | C10: CARDIOVASCULAR DISEASE | D10: ='Case 4'!E82 -> 3 | E10: ='Case 4'!E83 -> 3 | F10: ='Case 4'!E84 -> 3 | G10: ='Case 4'!E85 -> 4 | H10: ='Case 4'!E86 -> 3 | I10: ='Case 4'!E87 -> 3 | J10: ='Case 4'!E88 -> 3 | K10: ='Case 4'!E89 -> 3 | L10: ='Case 4'!E90 -> 4 | M10: =IFERROR(AVERAGE(D10,E10,F10,G10,H10,I10,J10,K10,L10),"—") -> 3.2222222 | P10: 4 | Q10: CARDIOVASCULAR DISEASE | R10: ='Case 4'!L82 -> 3 | S10: ='Case 4'!L83 -> 3 | T10: ='Case 4'!L84 -> 3 | U10: ='Case 4'!L85 -> 3 | V10: ='Case 4'!L86 -> 3 | W10: ='Case 4'!L87 -> 3 | X10: ='Case 4'!L88 -> 3 | Y10: ='Case 4'!L89 -> 4 | Z10: ='Case 4'!L90 -> 4 | AA10: =IFERROR(AVERAGE(R10,S10,T10,U10,V10,W10,X10,Y10,Z10),"—") -> 3.2222222
B11: 5 | C11: HYPERCHOLESTEROLEMIA | D11: ='Case 5'!E82 -> 3 | E11: ='Case 5'!E83 -> 3 | F11: ='Case 5'!E84 -> 4 | G11: ='Case 5'!E85 -> 4 | H11: ='Case 5'!E86 -> 4 | I11: ='Case 5'!E87 -> 4 | J11: ='Case 5'!E88 -> 3 | K11: ='Case 5'!E89 -> 3 | L11: ='Case 5'!E90 -> 4 | M11: =IFERROR(AVERAGE(D11,E11,F11,G11,H11,I11,J11,K11,L11),"—") -> 3.5555556 | P11: 5 | Q11: HYPERCHOLESTEROLEMIA | R11: ='Case 5'!L82 -> 3 | S11: ='Case 5'!L83 -> 3 | T11: ='Case 5'!L84 -> 3 | U11: ='Case 5'!L85 -> 4 | V11: ='Case 5'!L86 -> 3 | W11: ='Case 5'!L87 -> 3 | X11: ='Case 5'!L88 -> 3 | Y11: ='Case 5'!L89 -> 4 | Z11: ='Case 5'!L90 -> 4 | AA11: =IFERROR(AVERAGE(R11,S11,T11,U11,V11,W11,X11,Y11,Z11),"—") -> 3.3333333
B12: 6 | C12: CHRONIC KIDNEY DISEASE STAGE 1 | D12: ='Case 6'!E81 -> 3 | E12: ='Case 6'!E82 -> 3 | F12: ='Case 6'!E83 -> 3 | G12: ='Case 6'!E84 -> 3 | H12: ='Case 6'!E85 -> 3 | I12: ='Case 6'!E86 -> 3 | J12: ='Case 6'!E87 -> 3 | K12: ='Case 6'!E88 -> 3 | L12: ='Case 6'!E89 -> 4 | M12: =IFERROR(AVERAGE(D12,E12,F12,G12,H12,I12,J12,K12,L12),"—") -> 3.1111111 | P12: 6 | Q12: CHRONIC KIDNEY DISEASE STAGE 1 | R12: ='Case 6'!L81 -> 3 | S12: ='Case 6'!L82 -> 3 | T12: ='Case 6'!L83 -> 3 | U12: ='Case 6'!L84 -> 3 | V12: ='Case 6'!L85 -> 3 | W12: ='Case 6'!L86 -> 3 | X12: ='Case 6'!L87 -> 3 | Y12: ='Case 6'!L88 -> 4 | Z12: ='Case 6'!L89 -> 4 | AA12: =IFERROR(AVERAGE(R12,S12,T12,U12,V12,W12,X12,Y12,Z12),"—") -> 3.2222222
B13: 7 | C13: DIABETES + HYPERTENSION | D13: ='Case 7'!E81 -> 3 | E13: ='Case 7'!E82 -> 3 | F13: ='Case 7'!E83 -> 3 | G13: ='Case 7'!E84 -> 4 | H13: ='Case 7'!E85 -> 3 | I13: ='Case 7'!E86 -> 3 | J13: ='Case 7'!E87 -> 3 | K13: ='Case 7'!E88 -> 3 | L13: ='Case 7'!E89 -> 4 | M13: =IFERROR(AVERAGE(D13,E13,F13,G13,H13,I13,J13,K13,L13),"—") -> 3.2222222 | P13: 7 | Q13: DIABETES + HYPERTENSION | R13: ='Case 7'!L81 -> 3 | S13: ='Case 7'!L82 -> 3 | T13: ='Case 7'!L83 -> 3 | U13: ='Case 7'!L84 -> 4 | V13: ='Case 7'!L85 -> 3 | W13: ='Case 7'!L86 -> 3 | X13: ='Case 7'!L87 -> 3 | Y13: ='Case 7'!L88 -> 4 | Z13: ='Case 7'!L89 -> 4 | AA13: =IFERROR(AVERAGE(R13,S13,T13,U13,V13,W13,X13,Y13,Z13),"—") -> 3.3333333
B14: 8 | C14: DIABETES + HYPERCHOLESTEROLEMIA | D14: ='Case 8'!E82 -> 3 | E14: ='Case 8'!E83 -> 3 | F14: ='Case 8'!E84 -> 3 | G14: ='Case 8'!E85 -> 3 | H14: ='Case 8'!E86 -> 3 | I14: ='Case 8'!E87 -> 3 | J14: ='Case 8'!E88 -> 3 | K14: ='Case 8'!E89 -> 4 | L14: ='Case 8'!E90 -> 4 | M14: =IFERROR(AVERAGE(D14,E14,F14,G14,H14,I14,J14,K14,L14),"—") -> 3.2222222 | P14: 8 | Q14: DIABETES + HYPERCHOLESTEROLEMIA | R14: ='Case 8'!L82 -> 3 | S14: ='Case 8'!L83 -> 3 | T14: ='Case 8'!L84 -> 3 | U14: ='Case 8'!L85 -> 3 | V14: ='Case 8'!L86 -> 3 | W14: ='Case 8'!L87 -> 3 | X14: ='Case 8'!L88 -> 3 | Y14: ='Case 8'!L89 -> 4 | Z14: ='Case 8'!L90 -> 4 | AA14: =IFERROR(AVERAGE(R14,S14,T14,U14,V14,W14,X14,Y14,Z14),"—") -> 3.2222222
B15: 9 | C15: HYPERTENSION + CARDIOVASCULAR DISEASE | D15: ='Case 9'!E82 -> 3 | E15: ='Case 9'!E83 -> 3 | F15: ='Case 9'!E84 -> 3 | G15: ='Case 9'!E85 -> 3 | H15: ='Case 9'!E86 -> 3 | I15: ='Case 9'!E87 -> 3 | J15: ='Case 9'!E88 -> 3 | K15: ='Case 9'!E89 -> 3 | L15: ='Case 9'!E90 -> 4 | M15: =IFERROR(AVERAGE(D15,E15,F15,G15,H15,I15,J15,K15,L15),"—") -> 3.1111111 | P15: 9 | Q15: HYPERTENSION + CARDIOVASCULAR DISEASE | R15: ='Case 9'!L82 -> 3 | S15: ='Case 9'!L83 -> 3 | T15: ='Case 9'!L84 -> 3 | U15: ='Case 9'!L85 -> 3 | V15: ='Case 9'!L86 -> 3 | W15: ='Case 9'!L87 -> 3 | X15: ='Case 9'!L88 -> 3 | Y15: ='Case 9'!L89 -> 4 | Z15: ='Case 9'!L90 -> 4 | AA15: =IFERROR(AVERAGE(R15,S15,T15,U15,V15,W15,X15,Y15,Z15),"—") -> 3.2222222
B16: 10 | C16: CKD + HYPERTENSION | D16: ='Case 10'!E81 -> 3 | E16: ='Case 10'!E82 -> 3 | F16: ='Case 10'!E83 -> 3 | G16: ='Case 10'!E84 -> 4 | H16: ='Case 10'!E85 -> 3 | I16: ='Case 10'!E86 -> 3 | J16: ='Case 10'!E87 -> 3 | K16: ='Case 10'!E88 -> 3 | L16: ='Case 10'!E89 -> 4 | M16: =IFERROR(AVERAGE(D16,E16,F16,G16,H16,I16,J16,K16,L16),"—") -> 3.2222222 | P16: 10 | Q16: CKD + HYPERTENSION | R16: ='Case 10'!L81 -> 3 | S16: ='Case 10'!L82 -> 3 | T16: ='Case 10'!L83 -> 3 | U16: ='Case 10'!L84 -> 3 | V16: ='Case 10'!L85 -> 3 | W16: ='Case 10'!L86 -> 3 | X16: ='Case 10'!L87 -> 3 | Y16: ='Case 10'!L88 -> 4 | Z16: ='Case 10'!L89 -> 4 | AA16: =IFERROR(AVERAGE(R16,S16,T16,U16,V16,W16,X16,Y16,Z16),"—") -> 3.2222222
B17: 11 | C17: DIABETES + HYPERTENSION + HYPERCHOLESTEROLEMIA | D17: ='Case 11'!E82 -> 3 | E17: ='Case 11'!E83 -> 3 | F17: ='Case 11'!E84 -> 3 | G17: ='Case 11'!E85 -> 4 | H17: ='Case 11'!E86 -> 3 | I17: ='Case 11'!E87 -> 3 | J17: ='Case 11'!E88 -> 3 | K17: ='Case 11'!E89 -> 3 | L17: ='Case 11'!E90 -> 4 | M17: =IFERROR(AVERAGE(D17,E17,F17,G17,H17,I17,J17,K17,L17),"—") -> 3.2222222 | P17: 11 | Q17: DIABETES + HYPERTENSION + HYPERCHOLESTEROLEMIA | R17: ='Case 11'!L82 -> 3 | S17: ='Case 11'!L83 -> 3 | T17: ='Case 11'!L84 -> 3 | U17: ='Case 11'!L85 -> 3 | V17: ='Case 11'!L86 -> 3 | W17: ='Case 11'!L87 -> 3 | X17: ='Case 11'!L88 -> 3 | Y17: ='Case 11'!L89 -> 4 | Z17: ='Case 11'!L90 -> 4 | AA17: =IFERROR(AVERAGE(R17,S17,T17,U17,V17,W17,X17,Y17,Z17),"—") -> 3.2222222
B18: 12 | C18: CKD + DIABETES + HYPERTENSION | D18: ='Case 12'!E81 -> 3 | E18: ='Case 12'!E82 -> 3 | F18: ='Case 12'!E83 -> 3 | G18: ='Case 12'!E84 -> 3 | H18: ='Case 12'!E85 -> 3 | I18: ='Case 12'!E86 -> 3 | J18: ='Case 12'!E87 -> 3 | K18: ='Case 12'!E88 -> 4 | L18: ='Case 12'!E89 -> 4 | M18: =IFERROR(AVERAGE(D18,E18,F18,G18,H18,I18,J18,K18,L18),"—") -> 3.2222222 | P18: 12 | Q18: CKD + DIABETES + HYPERTENSION | R18: ='Case 12'!L81 -> 3 | S18: ='Case 12'!L82 -> 3 | T18: ='Case 12'!L83 -> 3 | U18: ='Case 12'!L84 -> 3 | V18: ='Case 12'!L85 -> 3 | W18: ='Case 12'!L86 -> 3 | X18: ='Case 12'!L87 -> 3 | Y18: ='Case 12'!L88 -> 4 | Z18: ='Case 12'!L89 -> 4 | AA18: =IFERROR(AVERAGE(R18,S18,T18,U18,V18,W18,X18,Y18,Z18),"—") -> 3.2222222
B19: 13 | C19: HYPERTENSION + HYPERCHOLESTEROLEMIA + CVD | D19: ='Case 13'!E82 -> 3 | E19: ='Case 13'!E83 -> 3 | F19: ='Case 13'!E84 -> 3 | G19: ='Case 13'!E85 -> 3 | H19: ='Case 13'!E86 -> 3 | I19: ='Case 13'!E87 -> 3 | J19: ='Case 13'!E88 -> 3 | K19: ='Case 13'!E89 -> 3 | L19: ='Case 13'!E90 -> 4 | M19: =IFERROR(AVERAGE(D19,E19,F19,G19,H19,I19,J19,K19,L19),"—") -> 3.1111111 | P19: 13 | Q19: HYPERTENSION + HYPERCHOLESTEROLEMIA + CVD | R19: ='Case 13'!L82 -> 3 | S19: ='Case 13'!L83 -> 3 | T19: ='Case 13'!L84 -> 3 | U19: ='Case 13'!L85 -> 3 | V19: ='Case 13'!L86 -> 3 | W19: ='Case 13'!L87 -> 3 | X19: ='Case 13'!L88 -> 3 | Y19: ='Case 13'!L89 -> 3 | Z19: ='Case 13'!L90 -> 4 | AA19: =IFERROR(AVERAGE(R19,S19,T19,U19,V19,W19,X19,Y19,Z19),"—") -> 3.1111111
B20: RATA-RATA PER KRITERIA → | D20: =IFERROR(AVERAGE(D7:D19),"—") -> 3.0769231 | E20: =IFERROR(AVERAGE(E7:E19),"—") -> 3.0769231 | F20: =IFERROR(AVERAGE(F7:F19),"—") -> 3.2307692 | G20: =IFERROR(AVERAGE(G7:G19),"—") -> 3.6153846 | H20: =IFERROR(AVERAGE(H7:H19),"—") -> 3.0769231 | I20: =IFERROR(AVERAGE(I7:I19),"—") -> 3.0769231 | J20: =IFERROR(AVERAGE(J7:J19),"—") -> 3 | K20: =IFERROR(AVERAGE(K7:K19),"—") -> 3.1538462 | L20: =IFERROR(AVERAGE(L7:L19),"—") -> 4 | M20: =IFERROR(AVERAGE(D20,E20,F20,G20,H20,I20,J20,K20,L20),"—") -> 3.2564103 | N20: Grand Average | P20: RATA-RATA PER KRITERIA → | R20: =IFERROR(AVERAGE(R7:R19),"—") -> 3.0769231 | S20: =IFERROR(AVERAGE(S7:S19),"—") -> 3.0769231 | T20: =IFERROR(AVERAGE(T7:T19),"—") -> 3.0769231 | U20: =IFERROR(AVERAGE(U7:U19),"—") -> 3.2307692 | V20: =IFERROR(AVERAGE(V7:V19),"—") -> 3 | W20: =IFERROR(AVERAGE(W7:W19),"—") -> 3 | X20: =IFERROR(AVERAGE(X7:X19),"—") -> 3 | Y20: =IFERROR(AVERAGE(Y7:Y19),"—") -> 3.9230769 | Z20: =IFERROR(AVERAGE(Z7:Z19),"—") -> 4 | AA20: =IFERROR(AVERAGE(R20,S20,T20,U20,V20,W20,X20,Y20,Z20),"—") -> 3.2649573 | AB20: Grand Average
B22: PANDUAN INTERPRETASI SKOR
B23: 1,00 – 1,99 | D23: Sangat Tidak Sesuai | H23: Perlu perombakan total pada sistem
B24: 2,00 – 2,99 | D24: Tidak Sesuai | H24: Perlu perbaikan signifikan
B25: 3,00 – 3,99 | D25: Cukup Sesuai | H25: Perlu perbaikan minor
B26: 4,00 – 4,59 | D26: Sesuai | H26: Layak dengan catatan kecil
B27: 4,60 – 5,00 | D27: Sangat Sesuai | H27: Layak direkomendasikan

Sheet Case 1
B2: CASE 1 — NORMAL
B5: BAGIAN 1 — PROFIL USER | D5: BAGIAN 2 — KEBUTUHAN NUTRISI USER
B6: Usia | C6: 28 | D6: BMR (kcal) | E6: 1703
B7: Jenis Kelamin | C7: Pria | D7: TDEE (kcal) | E7: 3142,1
B8: Berat Badan (kg) | C8: 68 | D8: Energi Harian (kcal) | E8: 2985.0 – 3299.2
B9: Tinggi Badan (cm) | C9: 178 | D9: Protein (g) | E9: 117.8 – 157.1
B10: Tingkat Aktivitas | C10: Sedang | D10: Lemak / Fat (g) | E10: 87.3 – 104.7
B11: Kondisi Penyakit | C11: Normal | D11: Karbohidrat (g) | E11: 429.1 – 474.3
D12: Air / Water (ml) | E12: ≥ 3700.0
B14: BAGIAN 3 — MENU YANG DIREKOMENDASIKAN SISTEM
B15: 🔵 GENETIC ALGORITHM (GA) | I15: 🟢 GREEDY ALGORITHM
B16: Waktu Makan | C16: Menu / Makanan | D16: Porsi (g/ml) | E16: Kalori (kcal) | I16: Waktu Makan | J16: Menu / Makanan | K16: Porsi (g/ml) | L16: Kalori (kcal)
B17: Breakfast — Main Course 1 | C17: Pan-Fried Ground Veal | D17: 150 g | E17: 322.5 | I17: Breakfast — Main Course 1 | J17: Mexican Bread Roll | K17: 115g | L17: 365,7 | M17: main course dan side dish kedunya roti? sebaiknya lebih bervarias
B18: Breakfast — Side Dish 1 | C18: Homemade Hummus | D18: 197 g | E18: 348.7 | F18: Porsi bisa dikurangi, sebaiknya kalori side dish < main course | I18: Breakfast — Side Dish 1 | J18: Dinner Rolls | K18: 78g | L18: 212,9
B19: Breakfast — Drink 1 | C19: Homemade Hot Chocolate | D19: 123 ml | E19: 94.7 | I19: Breakfast — Drink 1 | J19: Strawberry Shake | K19: 114ml | L19: 128,8
B21: Lunch — Main Course 1 | C21: Hush Puppies | D21: 153 g | E21: 515.6 | F21: double jagung (antara main course dan side dish), belum ada protein dan sayur | I21: Lunch — Main Course 1 | J21: Chow Mein Noodles | K21: 122g | L21: 574,6
B22: Lunch — Side Dish 1 | C22: White Corn | D22: 132 g | E22: 481.8 | F22: apakah tidak diolah? hanya jagung putih utuh? | I22: Lunch — Side Dish 1 | J22: Hard Rolls | K22: 105g | L22: 307,7 | M22: kenapa side dishnya hard rolls? jadi doubel karbo
B23: Lunch — Drink 1 | C23: Evaporated Milk | D23: 100 ml | E23: 107 | I23: Lunch — Drink 1 | J23: Strawberry Shake | K23: 121ml | L23: 136,7
B25: Dinner — Main Course 1 | C25: Toasted Wheat Germ Cereal | D25: 134 g | E25: 511.9 | F25: dari main course dam side dish belum ada protein dan sayur | I25: Dinner — Main Course 1 | J25: Hush Puppies | K25: 123g | L25: 414,5 | M25: kurang protein dan sayur
B26: Dinner — Side Dish 1 | C26: Cottage-Cut French Fries | D26: 119 g | E26: 259.4 | I26: Dinner — Side Dish 1 | J26: Oven-Heated French Fries | K26: 120g | L26: 232,8
B27: Dinner — Drink 1 | C27: Fruit Punch Drink | D27: 100 ml | E27: 175 | I27: Dinner — Drink 1 | J27: Strawberry Shake | K27: 122ml | L27: 137,9 | M27: untuk minum ketiga waktu makan sama, sebaiknya dibedakan salah satu waktu
B29: Snack — Option 1 | C29: Boiled European Chestnuts | D29: 240 g | E29: 314.4 | F29: porsi bisa dikurangin | I29: Snack — Option 1 | J29: Sugar-Free Cream-Filled Cookies | K29: 80g | L29: 424,8
B31: BAGIAN 4 — DISTRIBUSI KALORI PER WAKTU MAKAN
B32: 🔵 GENETIC ALGORITHM (GA) | I32: 🟢 Greedy — Distribusi Kalori
B33: Waktu Makan | C33: Kalori (kcal) | D33: % Target | E33: Keterangan | F33: Aktual | G33: Keterangan | I33: Waktu Makan | J33: Kalori (kcal) | K33: % Target | L33: Keterangan | M33: Aktual | N33: Keterangan
B34: Breakfast (Sarapan) | C34: 765,9 | D34: 0.2375 | E34: Konstanta sistem | F34: 0.244 | I34: Breakfast (Sarapan) | J34: 707.4 | K34: 0.2375 | L34: Konstanta sistem | M34: =J34/sum($J$34:$J$37) -> 0.24090723
B35: Lunch (Makan Siang) | C35: 1104,4 | D35: 0.3375 | E35: Konstanta sistem | F35: 0.351 | I35: Lunch (Makan Siang) | J35: 1019 | K35: 0.3375 | L35: Konstanta sistem | M35: =J35/sum($J$34:$J$37) -> 0.34702357
B36: Dinner (Makan Malam) | C36: 946,3 | D36: 0.2875 | E36: Konstanta sistem | F36: 0.301 | I36: Dinner (Makan Malam) | J36: 785.2 | K36: 0.2875 | L36: Konstanta sistem | M36: =J36/sum($J$34:$J$37) -> 0.26740226
B37: Snack | C37: 314,4 | D37: 0.1375 | E37: Konstanta sistem | F37: 0.1 | I37: Snack | J37: 424.8 | K37: 0.1375 | L37: Konstanta sistem | M37: =J37/sum($J$34:$J$37) -> 0.14466694
B39: BAGIAN 5 — EVALUASI HARD CONSTRAINT
B40: 🔵 GA — Hard Constraint | I40: 🟢 Greedy — Hard Constraint
B41: Nutrisi | C41: Min – Max | D41: Aktual (diisi peneliti) | E41: Keterpenuhan (%) | F41: Keterangan | I41: Nutrisi | J41: Min – Max | K41: Aktual (diisi peneliti) | L41: Keterpenuhan (%)
B42: Energy (kcal) | C42: 2985.0 – 3299.2 | D42: 3098.5 | E42: 1 | I42: Energy (kcal) | J42: 2985.0 – 3299.2 | K42: 2936.4 | L42: 0.984
B43: Protein (g) | C43: 117.8 – 157.1 | D43: 131.7 | E43: 1 | I43: Protein (g) | J43: 117.8 – 157.1 | K43: 70.6 | L43: 0.599
B44: Fat (g) | C44: 87.3 – 104.7 | D44: 94.5 | E44: 1 | I44: Fat (g) | J44: 87.3 – 104.7 | K44: 99.6 | L44: 1
B45: Carbohydrate (g) | C45: 429.1 – 474.3 | D45: 455.93 | E45: 1 | I45: Carbohydrate (g) | J45: 429.1 – 474.3 | K45: 448.1 | L45: 1
B46: Sodium (mg) | C46: 1500.0 – 2300.0 | D46: 2051.81 | E46: 1 | I46: Sodium (mg) | J46: 1500.0 – 2300.0 | K46: 4273.1 | L46: =K46/2300 -> 1.8578696
B47: Sugar (g) | C47: ≤ 39.3 | D47: 32.64 | E47: 1 | I47: Sugar (g) | J47: ≤ 39.3 | K47: 10.1 | L47: 1
B48: Cholesterol (mg) | C48: ≤ 300.0 | D48: 194.19 | E48: 1 | I48: Cholesterol (mg) | J48: ≤ 300.0 | K48: 95.8 | L48: 1
B49: Saturated Fat (g) | C49: ≤ 34.9 | D49: 23.66 | E49: 1 | I49: Saturated Fat (g) | J49: ≤ 34.9 | K49: 25.3 | L49: 1
...

Sheet Case 2
B2: CASE 2 — DIABETES MELITUS TYPE 2
B5: BAGIAN 1 — PROFIL USER | D5: BAGIAN 2 — KEBUTUHAN NUTRISI USER
B6: Usia | C6: 28 | D6: BMR (kcal) | E6: 1657,5
B7: Jenis Kelamin | C7: Pria | D7: TDEE (kcal) | E7: 2200
B8: Berat Badan (kg) | C8: 68 | D8: Energi Harian (kcal) | E8: 1800.0 – 2200.0
B9: Tinggi Badan (cm) | C9: 178 | D9: Protein (g) | E9: 66.0 – 82.5
B10: Tingkat Aktivitas | C10: Sedang | D10: Lemak / Fat (g) | E10: ≤ 73.3
B11: Kondisi Penyakit | C11: DM2 | D11: Karbohidrat (g) | E11: 274.3 – 303.2
D12: Air / Water (ml) | E12: ≥ 3700.0
B14: BAGIAN 3 — MENU YANG DIREKOMENDASIKAN SISTEM
B15: 🔵 GENETIC ALGORITHM (GA) | I15: 🟢 GREEDY ALGORITHM
B16: Waktu Makan | C16: Menu / Makanan | D16: Porsi (g/ml) | E16: Kalori (kcal) | F16: (diisi peneliti) | I16: Waktu Makan | J16: Menu / Makanan | K16: Porsi (g/ml) | L16: Kalori (kcal) | M16: (diisi peneliti)
B17: Breakfast — Main Course 1 | C17: Fish Sandwich with Tartar Sauce | D17: 113 | E17: 315.3 | I17: Breakfast — Main Course 1 | J17: Salmon Nuggets | K17: 138g | L17: 260,8 | M17: sebaiknya tidak menggunakan produk olahan
B18: Breakfast — Side Dish 1 | C18: Baked Butternut Squash | D18: 112 | E18: 44.8 | I18: Breakfast — Side Dish 1 | J18: Poi | K18: 137g | L18: 153,4 | M18: kurang sayur
B19: Breakfast — Drink 1 | C19: Canned Purple Plums | D19: 112 | E19: 113.1 | F19: diganti saja, menu ini tinggi gula (39 gr) | I19: Breakfast — Drink 1 | J19: Canned Purple Plums | K19: 100ml | L19: 101 | M19: diganti saja, menu ini tinggi gula (39 gr)
B21: Lunch — Main Course 1 | C21: Rice and Black Beans | D21: 246 | E21: 371.5 | F21: bisa dikurangi porsinya | I21: Lunch — Main Course 1 | J21: Cheese Pizza | K21: 139g | L21: 361,4 | M21: sebaiknya tidak menggunakan produk olahan
B22: Lunch — Side Dish 1 | C22: Homemade Hummus | D22: 126 | E22: 223 | I22: Lunch — Side Dish 1 | J22: Homemade Hummus | K22: 121g | L22: 214,2 | M22: kurang sayur
B23: Lunch — Drink 1 | C23: Evaporated Milk | D23: 111 | E23: 148.7 | I23: Lunch — Drink 1 | J23: Canned Purple Plums | K23: 138ml | L23: 139,4 | M23: diganti saja, menu ini tinggi gula (39 gr)
B25: Dinner — Main Course 1 | C25: Breaded Salmon Nuggets | D25: 123 | E25: 260.8 | F25: sebaiknya tidak menggunakan produk olahan | I25: Dinner — Main Course 1 | J25: Bean Pupusas | K25: 132g | L25: 302,3 | M25: apakah sudah termasuk sayur?
B26: Dinner — Side Dish 1 | C26: Cowpeas | D26: 122 | E26: 118.3 | F26: karbo dan sayur belum ada | I26: Dinner — Side Dish 1 | J26: Cottage-Cut French Fries | K26: 83g | L26: 180,9
B27: Dinner — Drink 1 | C27: Lowfat Milk | D27: 122 | E27: 58.6 | I27: Dinner — Drink 1 | J27: Strawberry Shake | K27: 108ml | L27: 122
B29: Snack — Option 1 | C29: Roasted Chestnuts | D29: 127 | E29: 303.5 | I29: Snack — Option 1 | J29: Plain Melba Toast | K29: 78g | L29: 304,2
B31: BAGIAN 4 — DISTRIBUSI KALORI PER WAKTU MAKAN
B32: 🔵 GA — Distribusi Kalori | I32: 🟢 Greedy — Distribusi Kalori
B33: Waktu Makan | C33: Kalori (kcal) | D33: % Target | E33: Keterangan | F33: Aktual | G33: Keterangan | I33: Waktu Makan | J33: Kalori (kcal) | K33: % Target | L33: Keterangan | M33: Aktual | N33: Keterangan
B34: Breakfast (Sarapan) | C34: 473,2 | D34: 23,75% | E34: Konstanta sistem | F34: 0.215 | I34: Breakfast (Sarapan) | J34: 515.2 | K34: 0.2375 | L34: Konstanta sistem | M34: =J34/sum($J$34:$J$37) -> 0.24079267
B35: Lunch (Makan Siang) | C35: 743,2 | D35: 33,75% | E35: Konstanta sistem | F35: 0.338 | I35: Lunch (Makan Siang) | J35: 715 | K35: 0.3375 | L35: Konstanta sistem | M35: =J35/sum($J$34:$J$37) -> 0.33417461
B36: Dinner (Makan Malam) | C36: 437,7 | D36: 28,75% | E36: Konstanta sistem | F36: 0.199 | I36: Dinner (Makan Malam) | J36: 605.2 | K36: 0.2875 | L36: Konstanta sistem | M36: =J36/sum($J$34:$J$37) -> 0.28285661
B37: Snack | C37: 303,5 | D37: 13,75% | E37: Konstanta sistem | F37: 0.138 | I37: Snack | J37: 304.2 | K37: 0.1375 | L37: Konstanta sistem | M37: =J37/sum($J$34:$J$37) -> 0.14217611
B39: BAGIAN 5 — EVALUASI HARD CONSTRAINT
B40: 🔵 GA — Hard Constraint | I40: 🟢 Greedy — Hard Constraint
B41: Nutrisi | C41: Min – Max | D41: Aktual (diisi peneliti) | E41: Keterpenuhan (%) | F41: Keterangan | I41: Nutrisi | J41: Min – Max | K41: Aktual (diisi peneliti) | L41: Keterpenuhan (%)
B42: Energy (kcal) | C42: 1800.0 – 2200.0 | D42: 1957.6 | E42: 1 | I42: Energy (kcal) | J42: 1800.0 – 2200.0 | K42: 2139.6 | L42: 1
B43: Protein (g) | C43: 66.0 – 82.5 | D43: 69.18 | E43: 1 | I43: Protein (g) | J43: 66.0 – 82.5 | K43: 64.3 | L43: 0.975
B44: Fat (g) | C44: ≤ 73.3 | D44: 63.25 | E44: 1 | I44: Fat (g) | J44: ≤ 73.3 | K44: 61.6 | L44: 1
B45: Carbohydrate (g) | C45: 274.3 – 303.2 | D45: 282.74 | E45: 1 | I45: Carbohydrate (g) | J45: 274.3 – 303.2 | K45: 336.3 | L45: =K45/303.2 -> 1.1091689
B46: Sodium (mg) | C46: ≤ 2300.0 | D46: 2265.47 | E46: 1 | I46: Sodium (mg) | J46: ≤ 2300.0 | K46: 1902.2 | L46: 1
B47: Sugar (g) | C47: ≤ 27.5 | D47: 23.9 | E47: 1 | I47: Sugar (g) | J47: ≤ 27.5 | K47: 9.7 | L47: 1
B48: Cholesterol (mg) | C48: ≤ 300.0 | D48: 110.86 | E48: 1 | I48: Cholesterol (mg) | J48: ≤ 300.0 | K48: 71.4 | L48: 1
B49: Serat / Fiber (g) | C49: 20.0 – 35.0 | D49: 25.1 | E49: 1 | I49: Serat / Fiber (g) | J49: 20.0 – 35.0 | K49: 26.9 | L49: 1
...

Sheet Case 3
B2: CASE 3 — HYPERTENSION
B5: BAGIAN 1 — PROFIL USER | D5: BAGIAN 2 — KEBUTUHAN NUTRISI USER
B6: Usia | C6: 28 | D6: BMR (kcal) | E6: 1657,5
B7: Jenis Kelamin | C7: Pria | D7: TDEE (kcal) | E7: 2205
B8: Berat Badan (kg) | C8: 68 | D8: Energi Harian (kcal) | E8: 1995.0 – 2205.0
B9: Tinggi Badan (cm) | C9: 178 | D9: Protein (g) | E9: 82.7 – 99.2
B10: Tingkat Aktivitas | C10: Sedang | D10: Lemak / Fat (g) | E10: 60.5 – 66.9
B11: Kondisi Penyakit | C11: Hipertensi | D11: Karbohidrat (g) | E11: 209.5 – 303.2
D12: Air / Water (ml) | E12: ≥ 3700.0
B14: BAGIAN 3 — MENU YANG DIREKOMENDASIKAN SISTEM
B15: 🔵 GENETIC ALGORITHM (GA) | I15: 🟢 GREEDY ALGORITHM
B16: Waktu Makan | C16: Menu / Makanan | D16: Porsi (g/ml) | E16: Kalori (kcal) | I16: Waktu Makan | J16: Menu / Makanan | K16: Porsi (g/ml) | L16: Kalori (kcal)
B17: Breakfast — Main Course 1 | C17: Frozen Fish Sticks | D17: 114 | E17: 315.8 | F17: Sebaiknya tidak menggunakan produk olahan | I17: Breakfast — Main Course 1 | J17: Whole Wheat French Bread | K17: 132g | L17: 315,5
B18: Breakfast — Side Dish 1 | C18: Baby Lima Beans | D18: 113 | E18: 118.7 | F18: bisa ditambahkan karbo | I18: Breakfast — Side Dish 1 | J18: Poi | K18: 131g | L18: 146,7
B19: Breakfast — Drink 1 | C19: Creamy Vegetable Oil Milk | D19: 113 | E19: 71.2 | F19: sayur yang digunakan apa saja? | I19: Breakfast — Drink 1 | J19: Unsweetened Pineapple Juice | K19: 100ml | L19: 53
B21: Lunch — Main Course 1 | C21: Tuna Sub Sandwich | D21: 171 | E21: 372.8 | F21: porsinya dikurangi, bisa di 100-150 g | I21: Lunch — Main Course 1 | J21: Homemade Falafel | K21: 130g | L21: 432,9
B22: Lunch — Side Dish 1 | C22: Boiled Safflower Seeds | D22: 170 | E22: 132.6 | I22: Lunch — Side Dish 1 | J22: Raisin Bread | K22: 87g | L22: 238,4
B23: Lunch — Drink 1 | C23: Evaporated Milk | D23: 139 | E23: 148.7 | I23: Lunch — Drink 1 | J23: Canned Purple Plums | K23: 100ml | L23: 101
B25: Dinner — Main Course 1 | C25: Hulled Barley | D25: 101 | E25: 357.5 | F25: kurang sayur | I25: Dinner — Main Course 1 | J25: Fried Tofu | K25: 134g | L25: 361,8 | M25: kurang karbo
B26: Dinner — Side Dish 1 | C26: Homemade Hummus | D26: 100 | E26: 177 | I26: Dinner — Side Dish 1 | J26: Lite Buttermilk Dressing | K26: 90g | L26: 181,8 | M26: apakah dengan sayur?
B27: Dinner — Drink 1 | C27: Lemon Juice | D27: 100 | E27: 17 | I27: Dinner — Drink 1 | J27: Canned Purple Plums | K27: 100ml | L27: 101
B29: Snack — Option 1 | C29: Frozen French Fries | D29: 206 | E29: 302.8 | F29: porsinya bisa dikurangi karena french fries jadi tinggi garam | I29: Snack — Option 1 | J29: Rye Melba Toast | K29: 78g | L29: 303,4 | M29: apakah terdapat campuran pada toast?
B31: BAGIAN 4 — DISTRIBUSI KALORI PER WAKTU MAKAN
B32: 🔵 GA — Distribusi Kalori | I32: 🟢 Greedy — Distribusi Kalori
B33: Waktu Makan | C33: Kalori (kcal) | D33: % Target | E33: Keterangan | F33: Aktual | G33: Keterangan | I33: Waktu Makan | J33: Kalori (kcal) | K33: % Target | L33: Keterangan | M33: Aktual | N33: Keterangan
B34: Breakfast (Sarapan) | C34: 505,6 | D34: 23,75% | E34: Konstanta sistem | F34: 0.229 | I34: Breakfast (Sarapan) | J34: 515.2 | K34: 0.2375 | L34: Konstanta sistem | M34: =J34/sum($J$34:$J$37) -> 0.23046298
B35: Lunch (Makan Siang) | C35: 654,1 | D35: 33,75% | E35: Konstanta sistem | F35: 0.297 | I35: Lunch (Makan Siang) | J35: 772.3 | K35: 0.3375 | L35: Konstanta sistem | M35: =J35/sum($J$34:$J$37) -> 0.34547081
B36: Dinner (Makan Malam) | C36: 551,5 | D36: 28,75% | E36: Konstanta sistem | F36: 0.25 | I36: Dinner (Makan Malam) | J36: 644.6 | K36: 0.2875 | L36: Konstanta sistem | M36: =J36/sum($J$34:$J$37) -> 0.28834713
B37: Snack | C37: 302,8 | D37: 13,75% | E37: Konstanta sistem | F37: 0.137 | I37: Snack | J37: 303.4 | K37: 0.1375 | L37: Konstanta sistem | M37: =J37/sum($J$34:$J$37) -> 0.13571908
B39: BAGIAN 5 — EVALUASI HARD CONSTRAINT
B40: 🔵 GA — Hard Constraint | I40: 🟢 Greedy — Hard Constraint
B41: Nutrisi | C41: Min – Max | D41: Aktual (diisi peneliti) | E41: Keterpenuhan (%) | F41: Keterangan | I41: Nutrisi | J41: Min – Max | K41: Aktual (diisi peneliti) | L41: Keterpenuhan (%)
B42: Energy (kcal) | C42: 1995.0 – 2205.0 | D42: 2014.09 | E42: 1 | I42: Energy (kcal) | J42: 1995.0 – 2205.0 | K42: 2235.5 | L42: =K42/2205 -> 1.0138322
B43: Protein (g) | C43: 82.7 – 99.2 | D43: 84.32 | E43: 1 | I43: Protein (g) | J43: 82.7 – 99.2 | K43: 72.1 | L43: 0.872
B44: Fat (g) | C44: 60.5 – 66.9 | D44: 66.87 | E44: 1 | I44: Fat (g) | J44: 60.5 – 66.9 | K44: 69.7 | L44: =K44/66.9 -> 1.0418535
B45: Carbohydrate (g) | C45: 209.5 – 303.2 | D45: 279.68 | E45: 1 | I45: Carbohydrate (g) | J45: 209.5 – 303.2 | K45: 344.2 | L45: =K45/303.2 -> 1.1352243
B46: Sodium (mg) | C46: ≤ 2300.0 | D46: 2281.03 | E46: 1 | I46: Sodium (mg) | J46: ≤ 2300.0 | K46: 3002.9 | L46: =K46/2300 -> 1.3056087
B47: Sugar (g) | C47: ≤ 27.6 | D47: 19.02 | E47: 1 | I47: Sugar (g) | J47: ≤ 27.6 | K47: 17.5 | L47: 1
B48: Cholesterol (mg) | C48: ≤ 150.0 | D48: 82.06 | E48: 1 | I48: Cholesterol (mg) | J48: ≤ 150.0 | K48: 14.4 | L48: 1
B49: Saturated Fat (g) | C49: ≤ 14.7 | D49: 14 | E49: 1 | I49: Saturated Fat (g) | J49: ≤ 14.7 | K49: 9.5 | L49: 1
...

Sheet Case 4
B2: CASE 4 — CARDIOVASCULAR DISEASE
B5: BAGIAN 1 — PROFIL USER | D5: BAGIAN 2 — KEBUTUHAN NUTRISI USER
B6: Usia | C6: 28 | D6: BMR (kcal) | E6: 1657,5
B7: Jenis Kelamin | C7: Pria | D7: TDEE (kcal) | E7: 3058,1
B8: Berat Badan (kg) | C8: 68 | D8: Energi Harian (kcal) | E8: 2905.2 – 3211.0
B9: Tinggi Badan (cm) | C9: 178 | D9: Protein (g) | E9: 114.7 – 191.1
B10: Tingkat Aktivitas | C10: Sedang | D10: Lemak / Fat (g) | E10: 85.0 – 118.9
B11: Kondisi Penyakit | C11: CVD | D11: Karbohidrat (g) | E11: 290.5 – 420.5
D12: Air / Water (ml) | E12: ≥ 3700.0
B14: BAGIAN 3 — MENU YANG DIREKOMENDASIKAN SISTEM
B15: 🔵 GENETIC ALGORITHM (GA) | I15: 🟢 GREEDY ALGORITHM
B16: Waktu Makan | C16: Menu / Makanan | D16: Porsi (g/ml) | E16: Kalori (kcal) | F16: (diisi peneliti) | I16: Waktu Makan | J16: Menu / Makanan | K16: Porsi (g/ml) | L16: Kalori (kcal) | M16: (diisi peneliti)
B17: Breakfast — Main Course 1 | C17: Pan-Fried Top Round Beef | D17: 100 g | E17: 228 | I17: Breakfast — Main Course 1 | J17: Homemade Falafel | K17: 111g | L17: 369,6
B18: Breakfast — Side Dish 1 | C18: Yellow Cornmeal | D18: 136 g | E18: 503.2 | I18: Breakfast — Side Dish 1 | J18: Corn Tortillas | K18: 95g | L18: 207,1
B19: Breakfast — Drink 1 | C19: Strawberry Banana Smoothie | D19: 100 ml | E19: 48 | I19: Breakfast — Drink 1 | J19: Canned Purple Plums | K19: 110ml | L19: 111,1
B21: Lunch — Main Course 1 | C21: Fried Tofu | D21: 157 g | E21: 423.9 | F21: kedua menu pengolahannya di goreng, bisa di ganti 1 menu non goreng | I21: Lunch — Main Course 1 | J21: Toasted Wheat Germ Cereal | K21: 140g | L21: 534,8 | M21: kurang protein
B22: Lunch — Side Dish 1 | C22: French Fries | D22: 172 g | E22: 536.6 | F22: kurangi porsinya, kurang sayur | I22: Lunch — Side Dish 1 | J22: Dried Cloud Ears | K22: 102g | L22: 289,7
B23: Lunch — Drink 1 | C23: Evaporated Milk | D23: 103 ml | E23: 110.2 | I23: Lunch — Drink 1 | J23: Low Fat Fruit Yogurt | K23: 139ml | L23: 141,8 | M23: buah apa saja yang dipake?
B25: Dinner — Main Course 1 | C25: Roasted Turkey | D25: 150 g | E25: 366 | I25: Dinner — Main Course 1 | J25: Cheesy Nachos | K25: 132g | L25: 452,8 | M25: kedua menu pengolahannya di goreng, bisa di ganti 1 menu non goreng
B26: Dinner — Side Dish 1 | C26: Cooked Frozen Peas and Carrots | D26: 305 g | E26: 146.4 | F26: kurangi porsinya dan tambah karbo | I26: Dinner — Side Dish 1 | J26: Thick-Cut Onion Rings | K26: 50g | L26: 163,5
B27: Dinner — Drink 1 | C27: Ensure Plus Drink | D27: 215 ml | E27: 303.1 | I27: Dinner — Drink 1 | J27: Strawberry Shake | K27: 131ml | L27: 148
B29: Snack — Option 1 | C29: Canned Kidney Beans | D29: 305 g | E29: 256.2 | F29: kurangi porsinya, terutama untuk menu kalengan | I29: Snack — Option 1 | J29: Peanut Butter Sandwich Cookies | K29: 79g | L29: 422,7
B31: BAGIAN 4 — DISTRIBUSI KALORI PER WAKTU MAKAN
B32: 🔵 GA — Distribusi Kalori | I32: 🟢 Greedy — Distribusi Kalori
B33: Waktu Makan | C33: Kalori (kcal) | D33: % Target | E33: Keterangan | F33: Aktual | I33: Waktu Makan | J33: Kalori (kcal) | K33: % Target | L33: Keterangan | M33: Keterangan
B34: Breakfast (Sarapan) | C34: 779,2 | D34: 23,75% | E34: Konstanta sistem | F34: 0.255 | I34: Breakfast (Sarapan) | J34: 687.8 | K34: 23,75% | L34: Konstanta sistem | M34: =J34/sum($J$34:$J$37) -> 0.24208933
B35: Lunch (Makan Siang) | C35: 1070,8 | D35: 33,75% | E35: Konstanta sistem | F35: 0.35 | I35: Lunch (Makan Siang) | J35: 966.3 | K35: 33,75% | L35: Konstanta sistem | M35: =J35/sum($J$34:$J$37) -> 0.34011474
B36: Dinner (Makan Malam) | C36: 815,6 | D36: 28,75% | E36: Konstanta sistem | F36: 0.267 | I36: Dinner (Makan Malam) | J36: 764.3 | K36: 28,75% | L36: Konstanta sistem | M36: =J36/sum($J$34:$J$37) -> 0.26901552
B37: Snack | C37: 256,2 | D37: 13,75% | E37: Konstanta sistem | F37: 0.084 | I37: Snack | J37: 422.7 | K37: 13,75% | L37: Konstanta sistem | M37: =J37/sum($J$34:$J$37) -> 0.1487804
B39: BAGIAN 5 — EVALUASI HARD CONSTRAINT
B40: 🔵 GA — Hard Constraint | I40: 🟢 Greedy — Hard Constraint
B41: Nutrisi | C41: Min – Max | D41: Aktual (diisi peneliti) | E41: Keterpenuhan (%) | F41: Keterangan | I41: Nutrisi | J41: Min – Max | K41: Aktual (diisi peneliti) | L41: Keterpenuhan (%)
B42: Energy (kcal) | C42: 2905.2 – 3211.0 | D42: 2921.6 | E42: 1 | I42: Energy (kcal) | J42: 2905.2 – 3211.0 | K42: 2841.1 | L42: 0.978
B43: Protein (g) | C43: 114.7 – 191.1 | D43: 162.73 | E43: 1 | I43: Protein (g) | J43: 114.7 – 191.1 | K43: 97.3 | L43: 0.848
B44: Fat (g) | C44: 85.0 – 118.9 | D44: 104.51 | E44: 1 | I44: Fat (g) | J44: 85.0 – 118.9 | K44: 106.7 | L44: 1
B45: Carbohydrate (g) | C45: 290.5 – 420.5 | D45: 340.6 | E45: 1 | I45: Carbohydrate (g) | J45: 290.5 – 420.5 | K45: 408.5 | L45: 1
B46: Sodium (mg) | C46: ≤ 2300.0 | D46: 1989.79 | E46: 1 | I46: Sodium (mg) | J46: ≤ 2300.0 | K46: 1590.8 | L46: 1
B47: Sugar (g) | C47: ≤ 38.2 | D47: 56.33 | E47: 1 | I47: Sugar (g) | J47: ≤ 38.2 | K47: 43.5 | L47: =K47/38.2 -> 1.1387435
B48: Cholesterol (mg) | C48: ≤ 300.0 | D48: 242.8 | E48: 1 | I48: Cholesterol (mg) | J48: ≤ 300.0 | K48: 23.9 | L48: 1
B49: Trans Fat (g) | C49: ≤ 3.4 | D49: 0.1 | E49: 1 | I49: Trans Fat (g) | J49: ≤ 3.4 | K49: 0.2 | L49: 1
...

Sheet Case 5
B2: CASE 5 — HYPERCHOLESTEROLEMIA
B5: BAGIAN 1 — PROFIL USER | D5: BAGIAN 2 — KEBUTUHAN NUTRISI USER
B6: Usia | C6: 28 | D6: BMR (kcal) | E6: 1657,5
B7: Jenis Kelamin | C7: Pria | D7: TDEE (kcal) | E7: 3058,1
B8: Berat Badan (kg) | C8: 68 | D8: Energi Harian (kcal) | E8: 2905.2 – 3211.0
B9: Tinggi Badan (cm) | C9: 178 | D9: Protein (g) | E9: 99.4 – 130.0
B10: Tingkat Aktivitas | C10: Sedang | D10: Lemak / Fat (g) | E10: 85.0 – 118.9
B11: Kondisi Penyakit | C11: Kolesterol | D11: Karbohidrat (g) | E11: ≤ 420.5
D12: Air / Water (ml) | E12: ≥ 3700.0
B14: BAGIAN 3 — MENU YANG DIREKOMENDASIKAN SISTEM
B15: 🔵 GENETIC ALGORITHM (GA) | I15: 🟢 GREEDY ALGORITHM
B16: Waktu Makan | C16: Menu / Makanan | D16: Porsi (g/ml) | E16: Kalori (kcal) | F16: (diisi peneliti) | I16: Waktu Makan | J16: Menu / Makanan | K16: Porsi (g/ml) | L16: Kalori (kcal) | M16: (diisi peneliti)
B17: Breakfast — Main Course 1 | C17: Navy Beans | D17: 314 | E17: 439.6 | F17: apakah ada campuran/pure navy beans? porsinya bisa dikurangi | I17: Breakfast — Main Course 1 | J17: Whole Wheat Chapati | K17: 121g | L17: 361,8 | M17: keduanya sama2 karbo, bisa diganti salah satunya dengan protein atau sayur yang cocok
B18: Breakfast — Side Dish 1 | C18: Plain Dinner Rolls | D18: 100 | E18: 316 | F18: kurang sayur | I18: Breakfast — Side Dish 1 | J18: Corn Tortillas | K18: 95g | L18: 207,1
B19: Breakfast — Drink 1 | C19: Plain Greek Yogurt | D19: 181 | E19: 175.6 | F19: apakah ada campuran buah? porsinya bisa dikurangi | I19: Breakfast — Drink 1 | J19: Canned Purple Plums | K19: 118ml | L19: 119,2
B21: Lunch — Main Course 1 | C21: Cheesy Nachos | D21: 150 | E21: 514.5 | I21: Lunch — Main Course 1 | J21: Oats | K21: 152g | L21: 591,3 | M21: perpaduan kedua menu kurang sesuai
B22: Lunch — Side Dish 1 | C22: Prepared Edamame | D22: 149 | E22: 180.3 | I22: Lunch — Side Dish 1 | J22: Dried Cloud Ears | K22: 106g | L22: 301
B23: Lunch — Drink 1 | C23: Strawberry Banana Smoothie | D23: 149 | E23: 71.5 | I23: Lunch — Drink 1 | J23: Low Fat Fruit Yogurt | K23: 100ml | L23: 102 | M23: buahnya pake apa aja?
B25: Dinner — Main Course 1 | C25: Fried Tofu | D25: 134 | E25: 361.8 | I25: Dinner — Main Course 1 | J25: Homemade Falafel | K25: 139g | L25: 462,9
B26: Dinner — Side Dish 1 | C26: White Corn | D26: 100 | E26: 365 | I26: Dinner — Side Dish 1 | J26: Plain Dinner Rolls | K26: 64g | L26: 202,2
B27: Dinner — Drink 1 | C27: Unsweetened Frozen Apple Juice | D27: 133 | E27: 62.5 | F27: jus kemasan? | I27: Dinner — Drink 1 | J27: Fruit Punch Drink | K27: 100ml | L27: 175
B29: Snack — Option 1 | C29: Roasted Chestnuts | D29: 209 | E29: 420.1 | F29: porsi bisa dikurangi | I29: Snack — Option 1 | J29: Oriental Rice Snack Mix | K29: 80g | L29: 404,8
B31: BAGIAN 4 — DISTRIBUSI KALORI PER WAKTU MAKAN
B32: 🔵 GA — Distribusi Kalori | I32: 🟢 Greedy — Distribusi Kalori
B33: Waktu Makan | C33: Kalori (kcal) | D33: % Target | E33: Keterangan | F33: Aktual | I33: Waktu Makan | J33: Kalori (kcal) | K33: % Target | L33: Keterangan | M33: Aktual
B34: Breakfast (Sarapan) | C34: 931,2 | D34: 23,75% | E34: Konstanta sistem | F34: 0.304 | I34: Breakfast (Sarapan) | J34: 688.1 | K34: 0.2375 | L34: Konstanta sistem | M34: =J34/sum($J$34:$J$37) -> 0.23506303
B35: Lunch (Makan Siang) | C35: 766,3 | D35: 33,75% | E35: Konstanta sistem | F35: 0.251 | I35: Lunch (Makan Siang) | J35: 994.3 | K35: 0.3375 | L35: Konstanta sistem | M35: =J35/sum($J$34:$J$37) -> 0.33966454
B36: Dinner (Makan Malam) | C36: 789,3 | D36: 28,75% | E36: Konstanta sistem | F36: 0.258 | I36: Dinner (Makan Malam) | J36: 840.1 | K36: 0.2875 | L36: Konstanta sistem | M36: =J36/sum($J$34:$J$37) -> 0.28698801
B37: Snack | C37: 420,1 | D37: 13,75% | E37: Konstanta sistem | F37: 0.137 | I37: Snack | J37: 404.8 | K37: 0.1375 | L37: Konstanta sistem | M37: =J37/sum($J$34:$J$37) -> 0.13828443
B39: BAGIAN 5 — EVALUASI HARD CONSTRAINT
B40: 🔵 GA — Hard Constraint | I40: 🟢 Greedy — Hard Constraint
B41: Nutrisi | C41: Min – Max | D41: Aktual (diisi peneliti) | E41: Keterpenuhan (%) | F41: Keterangan | I41: Nutrisi | J41: Min – Max | K41: Aktual (diisi peneliti) | L41: Keterpenuhan (%)
B42: Energy (kcal) | C42: 2905.2 – 3211.0 | D42: 2906.88 | E42: 1 | I42: Energy (kcal) | J42: 2905.2 – 3211.0 | K42: 2927.3 | L42: 1
B43: Protein (g) | C43: 99.4 – 130.0 | D43: 116.64 | E43: 1 | I43: Protein (g) | J43: 99.4 – 130.0 | K43: 93.3 | L43: 0.938
B44: Fat (g) | C44: 85.0 – 118.9 | D44: 92.36 | E44: 1 | I44: Fat (g) | J44: 85.0 – 118.9 | K44: 76.9 | L44: 0.905
B45: Carbohydrate (g) | C45: ≤ 420.5 | D45: 420.3 | E45: 1 | I45: Carbohydrate (g) | J45: ≤ 420.5 | K45: 489.3 | L45: =K45/420.5 -> 1.1636147
B46: Sodium (mg) | C46: ≤ 2300.0 | D46: 1065.23 | E46: 1 | I46: Sodium (mg) | J46: ≤ 2300.0 | K46: 1538.6 | L46: 1
B47: Sugar (g) | C47: ≤ 38.2 | D47: 33.3 | E47: 1 | I47: Sugar (g) | J47: ≤ 38.2 | K47: 25.8 | L47: 1
B48: Cholesterol (mg) | C48: ≤ 200.0 | D48: 63.03 | E48: 1 | I48: Cholesterol (mg) | J48: ≤ 200.0 | K48: 26.4 | L48: 1
B49: Saturated Fat (g) | C49: ≤ 23.8 | D49: 15.56 | E49: 1 | I49: Saturated Fat (g) | J49: ≤ 23.8 | K49: 14.6 | L49: 1
...

Sheet Case 6
B2: CASE 6 — CHRONIC KIDNEY DISEASE STAGE 1
B5: BAGIAN 1 — PROFIL USER | D5: BAGIAN 2 — KEBUTUHAN NUTRISI USER
B6: Usia | C6: 28 | D6: BMR (kcal) | E6: 1657,5
B7: Jenis Kelamin | C7: Pria | D7: TDEE (kcal) | E7: 2499
B8: Berat Badan (kg) | C8: 68 | D8: Energi Harian (kcal) | E8: 2261.0 – 2499.0
B9: Tinggi Badan (cm) | C9: 178 | D9: Protein (g) | E9: 40.8 – 54.4
B10: Tingkat Aktivitas | C10: Sedang | D10: Lemak / Fat (g) | E10: 69.4 – 97.2
B11: Kondisi Penyakit | C11: CKD | D11: Karbohidrat (g) | E11: 341.3 – 377.2
D12: Air / Water (ml) | E12: ≥ 3700.0
B14: BAGIAN 3 — MENU YANG DIREKOMENDASIKAN SISTEM
B15: 🔵 GENETIC ALGORITHM (GA) | I15: 🟢 GREEDY ALGORITHM
B16: Waktu Makan | C16: Menu / Makanan | D16: Porsi (g/ml) | E16: Kalori (kcal) | F16: (diisi peneliti) | I16: Waktu Makan | J16: Menu / Makanan | K16: Porsi (g/ml) | L16: Kalori (kcal) | M16: (diisi peneliti)
B17: Breakfast — Main Course 1 | C17: Beef and Cheese Taquitos | D17: 125 | E17: 358.8 | I17: Breakfast — Main Course 1 | J17: Plain Naan Bread | K17: 101g | L17: 293,9
B18: Breakfast — Side Dish 1 | C18: Cooked Cardoon | D18: 124 | E18: 27.3 | F18: cardoon itu apa? | I18: Breakfast — Side Dish 1 | J18: Cottage-Cut French Fries | K18: 100g | L18: 218,0 | M18: lebih baik diganti dengan protein hewani
B19: Breakfast — Drink 1 | C19: Unsweetened Apple Juice | D19: 124 | E19: 57 | I19: Breakfast — Drink 1 | J19: Unsweetened Grape Juice | K19: 100ml | L19: 60,0
B21: Lunch — Main Course 1 | C21: Fresh Spinach Pasta | D21: 146 | E21: 421.9 | I21: Lunch — Main Course 1 | J21: Cheesy Nachos | K21: 118g | L21: 404,7 | M21: perpaduan keduanya kurang sesuai, bisa diganti sayur/protein
B22: Lunch — Side Dish 1 | C22: Thick-Cut Onion Rings | D22: 100 | E22: 327 | F22: lebih baik diganti dengan protein hewani | I22: Lunch — Side Dish 1 | J22: Irish Soda Bread | K22: 78g | L22: 226,2
B23: Lunch — Drink 1 | C23: Coconut Milk | D23: 100 | E23: 197 | I23: Lunch — Drink 1 | J23: Canned Purple Plums | K23: 117ml | L23: 118,2
B25: Dinner — Main Course 1 | C25: Homemade Pasta | D25: 239 | E25: 296.4 | F25: bisa dikurangi porsinya | I25: Dinner — Main Course 1 | J25: Microwaved Buttermilk Waffle | K25: 102g | L25: 294,8 | M25: lebih cocok jadi breakfast/snack
B26: Dinner — Side Dish 1 | C26: Hash Brown Potatoes | D26: 100 | E26: 242 | F26: doubel karbo | I26: Dinner — Side Dish 1 | J26: Peanut Sauce | K26: 50g | L26: 128,5
B27: Dinner — Drink 1 | C27: Unsweetened Almond Milk | D27: 238 | E27: 35.7 | F27: kurangi porsinya, penderita ckd perlu pembatasan cairan | I27: Dinner — Drink 1 | J27: Canned Purple Plums | K27: 101ml | L27: 102
B29: Snack — Option 1 | C29: Peeled Chestnuts | D29: 175 | E29: 343 | F29: kurangi porsinya, penderita ckd perlu pembatasan protein nabati | I29: Snack — Option 1 | J29: Pecan Pie | K29: 80g | L29: 329,6
B31: BAGIAN 4 — DISTRIBUSI KALORI PER WAKTU MAKAN
B32: 🔵 GA — Distribusi Kalori | I32: 🟢 Greedy — Distribusi Kalori
B33: Waktu Makan | C33: Kalori (kcal) | D33: % Target | E33: Keterangan | F33: Aktual | I33: Waktu Makan | J33: Kalori (kcal) | K33: % Target | L33: Keterangan | M33: Aktual
B34: Breakfast (Sarapan) | C34: 443,1 | D34: 0.2375 | E34: Konstanta sistem | F34: 0.177 | I34: Breakfast (Sarapan) | J34: 571.9 | K34: 23,75% | L34: Konstanta sistem | M34: =J34/sum($J$34:$J$37) -> 0.26283377
B35: Lunch (Makan Siang) | C35: 945,9 | D35: 0.3375 | E35: Konstanta sistem | F35: 0.379 | I35: Lunch (Makan Siang) | J35: 749.1 | K35: 33,75% | L35: Konstanta sistem | M35: =J35/sum($J$34:$J$37) -> 0.34427134
B36: Dinner (Makan Malam) | C36: 574,1 | D36: 0.2875 | E36: Konstanta sistem | F36: 0.23 | I36: Dinner (Makan Malam) | J36: 525.3 | K36: 28,75% | L36: Konstanta sistem | M36: =J36/sum($J$34:$J$37) -> 0.24141734
B37: Snack | C37: 343,0 | D37: 0.1375 | E37: Konstanta sistem | F37: 0.137 | I37: Snack | J37: 329.6 | K37: 13,75% | L37: Konstanta sistem | M37: =J37/sum($J$34:$J$37) -> 0.15147755
B39: BAGIAN 5 — EVALUASI HARD CONSTRAINT
B40: 🔵 GA — Hard Constraint | I40: 🟢 Greedy — Hard Constraint
B41: Nutrisi | C41: Min – Max | D41: Aktual (diisi peneliti) | E41: Keterpenuhan (%) | F41: Keterangan | I41: Nutrisi | J41: Min – Max | K41: Aktual (diisi peneliti) | L41: Keterpenuhan (%)
B42: Energy (kcal) | C42: 2261.0 – 2499.0 | D42: 2306.07 | E42: 1 | I42: Energy (kcal) | J42: 2261.0 – 2499.0 | K42: 2175.9 | L42: 0.962
B43: Protein (g) | C43: 40.8 – 54.4 | D43: 53.53 | E43: 1 | I43: Protein (g) | J43: 40.8 – 54.4 | K43: 38.7 | L43: 0.948
B44: Fat (g) | C44: 69.4 – 97.2 | D44: 926.05 | E44: 1 | I44: Fat (g) | J44: 69.4 – 97.2 | K44: 78.9 | L44: 1
B45: Carbohydrate (g) | C45: 341.3 – 377.2 | D45: 362 | E45: 1 | I45: Carbohydrate (g) | J45: 341.3 – 377.2 | K45: 339.8 | L45: 0.996
B46: Sodium (mg) | C46: ≤ 2000.0 | D46: 1737.34 | E46: 1 | I46: Sodium (mg) | J46: ≤ 2000.0 | K46: 2795.7 | L46: =K46/2000 -> 1.39785
B47: Sugar (g) | C47: ≤ 31.2 | D47: 21.92 | E47: 1 | I47: Sugar (g) | J47: ≤ 31.2 | K47: 33.5 | L47: =K47/31.2 -> 1.0737179
B48: Cholesterol (mg) | C48: ≤ 300.0 | D48: 120.33 | E48: 1 | I48: Cholesterol (mg) | J48: ≤ 300.0 | K48: 103.5 | L48: 1
B49: Saturated Fat (g) | C49: ≤ 27.8 | D49: 27.62 | E49: 1 | I49: Saturated Fat (g) | J49: ≤ 27.8 | K49: 15.5 | L49: 1
...

Sheet Case 7
B2: CASE 7 — DIABETES + HYPERTENSION
B3: [DM] [HT] Dual : Gabungan guideline (DM) + (HT).
B5: BAGIAN 1 — PROFIL USER | D5: BAGIAN 2 — KEBUTUHAN NUTRISI USER
B6: Usia | C6: 55 | D6: BMR (kcal) | E6: 1103,5
B7: Jenis Kelamin | C7: Wanita | D7: TDEE (kcal) | E7: 1992,6
B8: Berat Badan (kg) | C8: 83 | D8: Energi Harian (kcal) | E8: 1992.6 – 2202.4
B9: Tinggi Badan (cm) | C9: 162 | D9: Protein (g) | E9: 71.0 – 78.5
B10: Tingkat Aktivitas | C10: Rendah | D10: Lemak / Fat (g) | E10: ≤ 60.4
B11: Kondisi Penyakit | C11: DM2 + Hipertensi | D11: Karbohidrat (g) | E11: 248.5 – 274.6
D12: Air / Water (ml) | E12: ≥ 2700.0
B14: BAGIAN 3 — MENU YANG DIREKOMENDASIKAN SISTEM
B15: 🔵 GENETIC ALGORITHM (GA) | I15: 🟢 GREEDY ALGORITHM
B16: Waktu Makan | C16: Menu / Makanan | D16: Porsi (g/ml) | E16: Kalori (kcal) | F16: (diisi peneliti) | I16: Waktu Makan | J16: Menu / Makanan | K16: Porsi (g/ml) | L16: Kalori (kcal) | M16: (diisi peneliti)
B17: Breakfast — Main Course 1 | C17: Canned Great Northern Beans | D17: 251 | E17: 286.1 | F17: kurangi porsinya | I17: Breakfast — Main Course 1 | J17: Fried Chicken Breast | K17: 165g | L17: 308,6
B18: Breakfast — Side Dish 1 | C18: Hash Brown Potatoes | D18: 100 | E18: 242 | I18: Breakfast — Side Dish 1 | J18: Poi | K18: 106g | L18: 118,7
B19: Breakfast — Drink 1 | C19: Chilled Orange Juice | D19: 199 | E19: 93.5 | F19: kurangi porsinya | I19: Breakfast — Drink 1 | J19: Canned Purple Plums | K19: 100ml | L19: 101 | M19: sebaiknya diganti karena tinggi gula
B21: Lunch — Main Course 1 | C21: Cheesy Nachos | D21: 101 | E21: 346.4 | F21: sebaiknya diganti menu lain karena menu ini tinggi sodium (garam) | I21: Lunch — Main Course 1 | J21: Whole Grain English Muffins | K21: 132g | L21: 323,4
B22: Lunch — Side Dish 1 | C22: Succotash | D22: 100 | E22: 115 | I22: Lunch — Side Dish 1 | J22: Shoestring French Fries | K22: 121g | L22: 197,2 | M22: sebaiknya diganti protein/sayur
B23: Lunch — Drink 1 | C23: Reduced Fat Milk | D23: 100 | E23: 51 | I23: Lunch — Drink 1 | J23: Canned Purple Plums | K23: 126ml | L23: 127,3 | M23: sebaiknya diganti karena tinggi gula
B25: Dinner — Main Course 1 | C25: Roasted Chicken | D25: 101 | E25: 236.3 | I25: Dinner — Main Course 1 | J25: Tuna Sub | K25: 101g | L25: 223,2 | M25: pakai sayuran kah?
B26: Dinner — Side Dish 1 | C26: French Fries | D26: 100 | E26: 312 | I26: Dinner — Side Dish 1 | J26: Homemade Hummus | K26: 98g | L26: 173,5
B27: Dinner — Drink 1 | C27: Lowfat Milk | D27: 100 | E27: 43 | I27: Dinner — Drink 1 | J27: Canned Purple Plums | K27: 100ml | L27: 101 | M27: sebaiknya diganti karena tinggi gula
B29: Snack — Option 1 | C29: Mixed-Grain English Muffins | D29: 117 | E29: 274.9 | I29: Snack — Option 1 | J29: Soft Pretzels | K29: 80g | L29: 270,4
B31: BAGIAN 4 — DISTRIBUSI KALORI PER WAKTU MAKAN
B32: 🔵 GA — Distribusi Kalori | I32: 🟢 Greedy — Distribusi Kalori
B33: Waktu Makan | C33: Kalori (kcal) | D33: % Target | E33: Keterangan | F33: Aktual | I33: Waktu Makan | J33: Kalori (kcal) | K33: % Target | L33: Keterangan | M33: Aktual
B34: Breakfast (Sarapan) | C34: 621,7 | D34: 23,75% | E34: Konstanta sistem | F34: 0.312 | I34: Breakfast (Sarapan) | J34: 528.3 | K34: 23,75% | L34: Konstanta sistem | M34: =J34/sum($J$34:$J$37) -> 0.27171733
B35: Lunch (Makan Siang) | C35: 512,4 | D35: 33,75% | E35: Konstanta sistem | F35: 0.257 | I35: Lunch (Makan Siang) | J35: 647.9 | K35: 33,75% | L35: Konstanta sistem | M35: =J35/sum($J$34:$J$37) -> 0.33323047
B36: Dinner (Makan Malam) | C36: 591,3 | D36: 28,75% | E36: Konstanta sistem | F36: 0.297 | I36: Dinner (Makan Malam) | J36: 497.7 | K36: 28,75% | L36: Konstanta sistem | M36: =J36/sum($J$34:$J$37) -> 0.25597902
B37: Snack | C37: 275,0 | D37: 13,75% | E37: Konstanta sistem | F37: 0.138 | I37: Snack | J37: 270.4 | K37: 13,75% | L37: Konstanta sistem | M37: =J37/sum($J$34:$J$37) -> 0.13907319
B39: BAGIAN 5 — EVALUASI HARD CONSTRAINT
B40: 🔵 GA — Hard Constraint | I40: 🟢 Greedy — Hard Constraint
B41: Nutrisi | C41: Min – Max | D41: Aktual (diisi peneliti) | E41: Keterpenuhan (%) | F41: Keterangan | I41: Nutrisi | J41: Min – Max | K41: Aktual (diisi peneliti) | L41: Keterpenuhan (%)
B42: Energy (kcal) | C42: 1992.6 – 2202.4 | D42: 2000.39 | E42: 1 | I42: Energy (kcal) | J42: 1992.6 – 2202.4 | K42: 1944.3 | L42: 0.976
B43: Protein (g) | C43: 71.0 – 78.5 | D43: 80.61 | E43: 1.027 | I43: Protein (g) | J43: 71.0 – 78.5 | K43: 92.4 | L43: =K43/78.5 -> 1.1770701
B44: Fat (g) | C44: ≤ 60.4 | D44: 67.17 | E44: 1.111 | I44: Fat (g) | J44: ≤ 60.4 | K44: 41.2 | L44: 0.753
B45: Carbohydrate (g) | C45: 248.5 – 274.6 | D45: 274.43 | E45: 1 | I45: Carbohydrate (g) | J45: 248.5 – 274.6 | K45: 304 | L45: =K45/274.6 -> 1.1070648
B46: Sodium (mg) | C46: ≤ 2300.0 | D46: 2085.26 | E46: 1 | I46: Sodium (mg) | J46: ≤ 2300.0 | K46: 1837.2 | L46: 1
B47: Sugar (g) | C47: ≤ 24.9 | D47: 24.68 | E47: 1 | I47: Sugar (g) | J47: ≤ 24.9 | K47: 5.4 | L47: 1
B48: Cholesterol (mg) | C48: ≤ 150.0 | D48: 123.1 | E48: 1 | I48: Cholesterol (mg) | J48: ≤ 150.0 | K48: 178.4 | L48: =K48/150 -> 1.1893333
...

Sheet Case 8
B2: CASE 8 — DIABETES + HYPERCHOLESTEROLEMIA
B3: [DM] [HK] Dual : Gabungan guideline (DM) + (HK).
B5: BAGIAN 1 — PROFIL USER | D5: BAGIAN 2 — KEBUTUHAN NUTRISI USER
B6: Usia | C6: 55 | D6: BMR (kcal) | E6: 1103,5
B7: Jenis Kelamin | C7: Wanita | D7: TDEE (kcal) | E7: 1705,3
B8: Berat Badan (kg) | C8: 83 | D8: Energi Harian (kcal) | E8: 1705.5 – 1885.1
B9: Tinggi Badan (cm) | C9: 162 | D9: Protein (g) | E9: 55.4 – 64.0
B10: Tingkat Aktivitas | C10: Rendah | D10: Lemak / Fat (g) | E10: ≤ 56.8
B11: Kondisi Penyakit | C11: DM2 + Kolesterol | D11: Karbohidrat (g) | E11: 212.6 – 235.0
D12: Air / Water (ml) | E12: ≥ 2700.0
B14: BAGIAN 3 — MENU YANG DIREKOMENDASIKAN SISTEM
B15: 🔵 GENETIC ALGORITHM (GA) | I15: 🟢 GREEDY ALGORITHM
B16: Waktu Makan | C16: Menu / Makanan | D16: Porsi (g/ml) | E16: Kalori (kcal) | F16: (diisi peneliti) | I16: Waktu Makan | J16: Menu / Makanan | K16: Porsi (g/ml) | L16: Kalori (kcal) | M16: (diisi peneliti)
B17: Breakfast — Main Course 1 | C17: Fish Sandwich with Tartar Sauce | D17: 101 | E17: 281.8 | I17: Breakfast — Main Course 1 | J17: Arroz con Habichuelas | K17: 151g | L17: 214,4
B18: Breakfast — Side Dish 1 | C18: Raw Sprouted Pinto Beans | D18: 100 | E18: 62 | F18: kecambah/tauge? | I18: Breakfast — Side Dish 1 | J18: Poi | K18: 110g | L18: 123,2 | M18: Kombinasinya kurang cocok
B19: Breakfast — Drink 1 | C19: 2% Reduced Fat Milk | D19: 100 | E19: 50 | I19: Breakfast — Drink 1 | J19: Canned Purple Plums | K19: 100ml | L19: 89 | M19: bisa diganti, tinggi gula
B21: Lunch — Main Course 1 | C21: Hush Puppies | D21: 101 | E21: 340.4 | I21: Lunch — Main Course 1 | J21: Bean Pupusas | K21: 121g | L21: 277,1 | M21: kurang cocok dijadikan lunch, lebih cocok jadi breakfast
B22: Lunch — Side Dish 1 | C22: Cooked Peas and Carrots | D22: 100 | E22: 48 | I22: Lunch — Side Dish 1 | J22: Homemade Hummus | K22: 94g | L22: 166,4
B23: Lunch — Drink 1 | C23: Goat Milk with Vitamin D | D23: 100 | E23: 69 | I23: Lunch — Drink 1 | J23: Canned Purple Plums | K23: 110ml | L23: 111,1 | M23: bisa diganti, tinggi gula
B25: Dinner — Main Course 1 | C25: Oats | D25: 101 | E25: 392.9 | I25: Dinner — Main Course 1 | J25: Salmon Nuggets | K25: 126g | L25: 238,1 | M25: diusahakan jangan makanan olahan
B26: Dinner — Side Dish 1 | C26: Homemade Hummus | D26: 100 | E26: 177 | F26: sebaiknya diganti protein hewani/sayur | I26: Dinner — Side Dish 1 | J26: Raw Eppaw | K26: 87g | L26: 130,5 | M26: ini apa?
B27: Dinner — Drink 1 | C27: Muscle Milk | D27: 100 | E27: 52 | I27: Dinner — Drink 1 | J27: Canned Purple Plums | K27: 100ml | L27: 101 | M27: bisa diganti, tinggi gula
B29: Snack — Option 1 | C29: Boiled Breadfruit Seeds | D29: 140 | E29: 235.2 | I29: Snack — Option 1 | J29: Blueberry Muffins | K29: 80g | L29: 228
B31: BAGIAN 4 — DISTRIBUSI KALORI PER WAKTU MAKAN
B32: 🔵 GA — Distribusi Kalori | I32: 🟢 Greedy — Distribusi Kalori
B33: Waktu Makan | C33: Kalori (kcal) | D33: % Target | E33: Keterangan | F33: Keterangan | I33: Waktu Makan | J33: Kalori (kcal) | K33: % Target | L33: Keterangan | M33: Aktual
B34: Breakfast (Sarapan) | C34: 393,8 | D34: 23,75% | E34: Konstanta sistem | F34: 0.231 | I34: Breakfast (Sarapan) | J34: 426.6 | K34: 23,75% | L34: Konstanta sistem | M34: =J34/sum($J$34:$J$37) -> 0.25411008
B35: Lunch (Makan Siang) | C35: 457,4 | D35: 33,75% | E35: Konstanta sistem | F35: 0.268 | I35: Lunch (Makan Siang) | J35: 554.6 | K35: 33,75% | L35: Konstanta sistem | M35: =J35/sum($J$34:$J$37) -> 0.33035502
B36: Dinner (Makan Malam) | C36: 621,9 | D36: 28,75% | E36: Konstanta sistem | F36: 0.365 | I36: Dinner (Makan Malam) | J36: 469.6 | K36: 28,75% | L36: Konstanta sistem | M36: =J36/sum($J$34:$J$37) -> 0.27972361
B37: Snack | C37: 235,2 | D37: 13,75% | E37: Konstanta sistem | F37: 0.138 | I37: Snack | J37: 228 | K37: 13,75% | L37: Konstanta sistem | M37: =J37/sum($J$34:$J$37) -> 0.13581129
B39: BAGIAN 5 — EVALUASI HARD CONSTRAINT
B40: 🔵 GA — Hard Constraint | I40: 🟢 Greedy — Hard Constraint
B41: Nutrisi | C41: Min – Max | D41: Aktual (diisi peneliti) | E41: Keterpenuhan (%) | F41: Keterangan | I41: Nutrisi | J41: Min – Max | K41: Aktual (diisi peneliti) | L41: Keterpenuhan (%)
